import { useCallback } from 'react';

import useAuthProvider from './useAuthProvider';
import useLogout from './useLogout';
import { useNotify } from '../sideEffect';

let authCheckPromise;

/**
 * Returns a callback used to call the authProvider.checkError() method
 * and an error from the dataProvider. If the authProvider rejects the call,
 * the hook logs the user out and shows a logged out notification.
 *
 * Used in the useDataProvider hook to check for access denied responses
 * (e.g. 401 or 403 responses) and trigger a logout.
 *
 * @see useLogout
 * @see useDataProvider
 *
 * @returns {Function} logoutIfAccessDenied callback
 *
 * @example
 *
 * import { useLogoutIfAccessDenied, useNotify, DataProviderContext } from 'react-admin';
 *
 * const FetchRestrictedResource = () => {
 *     const dataProvider = useContext(DataProviderContext);
 *     const logoutIfAccessDenied = useLogoutIfAccessDenied();
 *     const notify = useNotify()
 *     useEffect(() => {
 *         dataProvider.getOne('secret', { id: 123 })
 *             .catch(error => {
 *                  logoutIfAccessDenied(error);
 *                  notify('server error', 'warning');
 *              })
 *     }, []);
 *     // ...
 * }
 */
const useLogoutIfAccessDenied = (): LogoutIfAccessDenied => {
    const authProvider = useAuthProvider();
    const logout = useLogout();
    const notify = useNotify();
    const logoutIfAccessDenied = useCallback(
        (error?: any, disableNotification?: boolean) => {
            // Sometimes, a component might trigger multiple simultaneous
            // dataProvider calls which all fail and call this function.
            // To avoid having multiple notifications, we first verify if
            // a checkError promise is already ongoing
            if (!authCheckPromise) {
                authCheckPromise = authProvider
                    .checkError(error)
                    .then(() => false)
                    .catch(async e => {
                        const redirectTo =
                            e && e.redirectTo
                                ? e.redirectTo
                                : error && error.redirectTo
                                ? error.redirectTo
                                : undefined;
                        logout({}, redirectTo);
                        !disableNotification &&
                            notify('ra.notification.logged_out', 'warning');
                        return true;
                    })
                    .finally(() => {
                        authCheckPromise = undefined;
                    });
            }
            return authCheckPromise;
        },
        [authProvider, logout, notify]
    );
    return authProvider
        ? logoutIfAccessDenied
        : logoutIfAccessDeniedWithoutProvider;
};

const logoutIfAccessDeniedWithoutProvider = () => Promise.resolve(false);

/**
 * Call the authProvider.authError() method, unsing the error passed as argument.
 * If the authProvider rejects the call, logs the user out and shows a logged out notification.
 *
 * @param {Error} error An Error object (usually returned by the dataProvider)
 * @param {boolean} disableNotification Avoid showing a notification after the user is logged out. false by default.
 *
 * @return {Promise} Resolved to true if there was a logout, false otherwise
 */
type LogoutIfAccessDenied = (
    error?: any,
    disableNotification?: boolean
) => Promise<boolean>;

export default useLogoutIfAccessDenied;
